Workbook
Name Slicer_Customer_Segment: #N/A
Name Slicer_Store_Branch: #N/A

Sheet Sales_Transactions
A1: Transaction_ID | B1: Order_Date | C1: Customer_ID | D1: Gender | E1: Product_ID | F1: Quantity_Sold | G1: Unit_Cost_NGN | H1: Unit_Price_NGN | I1: Total_Revenue_NGN | J1: Total_Cost_NGN | K1: Profit_NGN | L1: Profit_Margin_Pct | M1: Store_Branch | N1: Payment_Method
A2: TXN-10001 | B2: 2026-04-13 | C2: CUST2001 | D2: female | E2: PRD103 | F2: 21 | G2: 1800 | H2: 2400 | I2: 50400 | J2: 37800 | K2: 12600 | L2: 25 | M2: lagos main | N2: pos
A3: TXN-10002 | B3: 2026-06-29 | C3: CUST2010 | D3: Female | E3: PRD105 | F3: 4 | G3: 2200 | H3: 2900 | I3: 11600 | J3: 8800 | K3: 2800 | L3: 24.14 | M3: Abuja Central | N3: Bank Transfer
A4: TXN-10003 | B4: 2026-04-03 | C4: CUST2010 | D4: Female | E4: PRD107 | F4: 1 | G4: 6500 | H4: 8500 | I4: 8500 | J4: 6500 | K4: 2000 | L4: 23.53 | M4: Port Harcourt Hub | N4: Cash
A5: TXN-10004 | B5: 2026-01-15 | C5: CUST2012 | D5: Female | E5: PRD109 | F5: 24 | G5: 750 | H5: 1100 | I5: 26400 | J5: 18000 | K5: 8400 | L5: 31.82 | M5: Kano Retail | N5: USSD
A6: TXN-10005 | B6: 2026-04-17 | C6: CUST2009 | D6: Male | E6: PRD107 | F6: 9 | G6: 6500 | H6: 8500 | I6: 76500 | J6: 58500 | K6: 18000 | L6: 23.53 | M6: Ibadan Depot | N6: POS
A7: TXN-10006 | B7: 2026-03-13 | C7: CUST2012 | D7: Female | E7: PRD108 | F7: 8 | G7: 600 | H7: 850 | I7: 6800 | J7: 4800 | K7: 2000 | L7: 29.41 | M7: Lagos Main | N7: Bank Transfer
A8: TXN-10007 | B8: 2026-01-21 | C8: CUST2001 | D8: Female | E8: PRD102 | F8: 8 | G8: 120 | H8: 180 | I8: 1440 | J8: 960 | K8: 480 | L8: 33.33 | M8: Abuja Central | N8: Cash
A9: TXN-10008 | B9: 2026-04-13 | C9: CUST2007 | D9: Female | E9: PRD107 | F9: 5 | G9: 6500 | H9: 8500 | I9: 42500 | J9: 32500 | K9: 10000 | L9: 23.53 | M9: port harcourt hub | N9: USSD
A10: TXN-10009 | B10: 2026-05-02 | C10: CUST2005 | D10: Female | E10: PRD108 | F10: 24 | G10: 600 | H10: 850 | I10: 20400 | J10: 14400 | K10: 6000 | L10: 29.41 | M10: Kano Retail | N10: POS
A11: TXN-10010 | B11: 2026-03-16 | C11: CUST2012 | D11: Female | E11: PRD103 | F11: 4 | G11: 1800 | H11: 2400 | I11: 9600 | J11: 7200 | K11: 2400 | L11: 25 | M11: Ibadan Depot | N11: bank transfer
A12: TXN-10011 | B12: 2026-03-29 | C12: CUST2006 | D12: Male | E12: PRD108 | F12: 22 | G12: 600 | H12: 850 | I12: 18700 | J12: 13200 | K12: 5500 | L12: 29.41 | M12: Lagos Main | N12: Cash
A13: TXN-10012 | B13: 2026-04-27 | C13: CUST2001 | D13: Female | E13: PRD103 | F13: 24 | G13: 1800 | H13: 2400 | I13: 57600 | J13: 43200 | K13: 14400 | L13: 25 | M13: Abuja Central | N13: USSD
... A101: TXN-10100 | B101: 2026-06-12 | C101: CUST2003 | D101: Female | E101: PRD109 | F101: 6 | G101: 750 | H101: 1100 | I101: 6600 | J101: 4500 | K101: 2100 | L101: 31.82 | M101: Ibadan Depot | N101: ussd

Sheet Dashboard

Sheet PIVOT_TABLES
A3: Row Labels | B3: Sum of Total_Revenue_NGN | C3: Sum of Profit_NGN
A4: Abuja Central | B4: 698960 | C4: 176170
A5: Ibadan Depot | B5: 576660 | C5: 147370
A6: Kano Retail | B6: 491360 | C6: 125670
A7: Lagos Main | B7: 472700 | C7: 120050
A8: Port Harcourt Hub | B8: 427520 | C8: 109190
A9: Grand Total | B9: 2667200 | C9: 678450
A11: Row Labels | B11: Sum of Total_Revenue_NGN | C11: Sum of Profit_NGN
A12: Beverages | B12: 223450 | C12: 69450
A13: Cooking Ingredients | B13: 389050 | C13: 100050
A14: Dairy | B14: 412800 | C14: 103200
A15: Grains | B15: 1351500 | C15: 318000
A16: Household | B16: 190800 | C16: 55650
A17: Packaged Food | B17: 13500 | C17: 4500
A18: Personal Care | B18: 86100 | C18: 27600
A19: Grand Total | B19: 2667200 | C19: 678450
A21: Row Labels | B21: Sum of Total_Revenue_NGN
A22: Corporate | B22: 628100
A23: Retail | B23: 1129580
A24: Wholesale | B24: 909520
A25: Grand Total | B25: 2667200
A27: Row Labels | B27: Sum of Total_Revenue_NGN
A28: January | B28: 441140
A29: February | B29: 569950
A30: March | B30: 411850
A31: April | B31: 399110
A32: May | B32: 368800
A33: June | B33: 476350
A34: Grand Total | B34: 2667200
A36: Row Labels | B36: Sum of Total_Revenue_NGN
A37: Basmati Rice 5kg | B37: 1351500
A38: Whole Milk Powder 400g | B38: 412800
A39: Vegetable Oil 1L | B39: 272600
A40: Laundry Detergent 1kg | B40: 190800
A41: Fruit Juice 1L | B41: 172700
A42: Tomato Paste 400g | B42: 116450
A43: Malt Beverage 33cl | B43: 50750
A44: Toilet Soap 120g | B44: 43200
A45: Toothpaste 140g | B45: 42900
A46: Instant Noodles 70g | B46: 13500
...

Sheet Cleaned_Sales_Data
A1: Transaction_ID | B1: Order_Date | C1: Month | D1: Customer_ID | E1: Customer_Name | F1: Gender | G1: Customer_Segment | H1: Location_State | I1: Product_ID | J1: Product Name | K1: Category | L1: Quantity_Sold | M1: Unit_Cost_NGN | N1: Unit_Price_NGN | O1: Total_Revenue_NGN | P1: Total_Cost_NGN | Q1: Profit_NGN | R1: Profit_Margin_Pct | S1: Store_Branch | T1: Payment_Method | U1: Column1 | V1: Column2 | W1: Column3
A2: TXN-10001 | B2: 13-Apr-2026 | C2: April | D2: CUST2001 | E2: Amina Bello | F2: Female | G2: Retail | H2: Lagos | I2: PRD103 | J2: =VLOOKUP(I2,Product_Catalog!$A$1:$E$11,2,FALSE) -> Whole Milk Powder 400g | K2: Dairy | L2: 21 | M2: 1800 | N2: 2400 | O2: 50400 | P2: 37800 | Q2: 12600 | R2: 0.25 | S2: Lagos Main | T2: POS
A3: TXN-10002 | B3: 29-Jun-2026 | C3: June | D3: CUST2010 | E3: Blessing John | F3: Female | G3: Retail | H3: Abuja | I3: PRD105 | J3: =VLOOKUP(I3,Product_Catalog!$A$1:$E$11,2,FALSE) -> Vegetable Oil 1L | K3: Cooking Ingredients | L3: 4 | M3: 2200 | N3: 2900 | O3: 11600 | P3: 8800 | Q3: 2800 | R3: 0.24137931 | S3: Abuja Central | T3: BANK TRANSFER
A4: TXN-10003 | B4: 03-Apr-2026 | C4: April | D4: CUST2010 | E4: Blessing John | F4: Female | G4: Retail | H4: Abuja | I4: PRD107 | J4: =VLOOKUP(I4,Product_Catalog!$A$1:$E$11,2,FALSE) -> Basmati Rice 5kg | K4: Grains | L4: 1 | M4: 6500 | N4: 8500 | O4: 8500 | P4: 6500 | Q4: 2000 | R4: 0.23529412 | S4: Port Harcourt Hub | T4: CASH | U4: =COUNTA(A2:A101) -> 100
A5: TXN-10004 | B5: 15-Jan-2026 | C5: January | D5: CUST2012 | E5: Fatima Abubakar | F5: Female | G5: Retail | H5: Kano | I5: PRD109 | J5: =VLOOKUP(I5,Product_Catalog!$A$1:$E$11,2,FALSE) -> Fruit Juice 1L | K5: Beverages | L5: 24 | M5: 750 | N5: 1100 | O5: 26400 | P5: 18000 | Q5: 8400 | R5: 0.31818182 | S5: Kano Retail | T5: USSD
A6: TXN-10005 | B6: 17-Apr-2026 | C6: April | D6: CUST2009 | E6: Yinka Ogundipe | F6: Male | G6: Corporate | H6: Lagos | I6: PRD107 | J6: =VLOOKUP(I6,Product_Catalog!$A$1:$E$11,2,FALSE) -> Basmati Rice 5kg | K6: Grains | L6: 9 | M6: 6500 | N6: 8500 | O6: 76500 | P6: 58500 | Q6: 18000 | R6: 0.23529412 | S6: Ibadan Depot | T6: POS
A7: TXN-10006 | B7: 13-Mar-2026 | C7: March | D7: CUST2012 | E7: Fatima Abubakar | F7: Female | G7: Retail | H7: Kano | I7: PRD108 | J7: =VLOOKUP(I7,Product_Catalog!$A$1:$E$11,2,FALSE) -> Tomato Paste 400g | K7: Cooking Ingredients | L7: 8 | M7: 600 | N7: 850 | O7: 6800 | P7: 4800 | Q7: 2000 | R7: 0.29411765 | S7: Lagos Main | T7: BANK TRANSFER | V7: AVG PROFIT MARGIN | W7: =AVERAGE(R:R) -> 0.28351927
A8: TXN-10007 | B8: 21-Jan-2026 | C8: January | D8: CUST2001 | E8: Amina Bello | F8: Female | G8: Retail | H8: Lagos | I8: PRD102 | J8: =VLOOKUP(I8,Product_Catalog!$A$1:$E$11,2,FALSE) -> Instant Noodles 70g | K8: Packaged Food | L8: 8 | M8: 120 | N8: 180 | O8: 1440 | P8: 960 | Q8: 480 | R8: 0.33333333 | S8: Abuja Central | T8: CASH | V8: TOTAL UNIT SOLD | W8: =SUM(L:L) -> 1260
A9: TXN-10008 | B9: 13-Apr-2026 | C9: April | D9: CUST2007 | E9: Ngozi Eze | F9: Female | G9: Retail | H9: Rivers | I9: PRD107 | J9: =VLOOKUP(I9,Product_Catalog!$A$1:$E$11,2,FALSE) -> Basmati Rice 5kg | K9: Grains | L9: 5 | M9: 6500 | N9: 8500 | O9: 42500 | P9: 32500 | Q9: 10000 | R9: 0.23529412 | S9: Port Harcourt Hub | T9: USSD | V9: TOTAL TRANSACTIONS | W9: =COUNTA(A2:A101) -> 100
A10: TXN-10009 | B10: 02-May-2026 | C10: May | D10: CUST2005 | E10: Zainab Ibrahim | F10: Female | G10: Retail | H10: Lagos | I10: PRD108 | J10: =VLOOKUP(I10,Product_Catalog!$A$1:$E$11,2,FALSE) -> Tomato Paste 400g | K10: Cooking Ingredients | L10: 24 | M10: 600 | N10: 850 | O10: 20400 | P10: 14400 | Q10: 6000 | R10: 0.29411765 | S10: Kano Retail | T10: POS
A11: TXN-10010 | B11: 16-Mar-2026 | C11: March | D11: CUST2012 | E11: Fatima Abubakar | F11: Female | G11: Retail | H11: Kano | I11: PRD103 | J11: =VLOOKUP(I11,Product_Catalog!$A$1:$E$11,2,FALSE) -> Whole Milk Powder 400g | K11: Dairy | L11: 4 | M11: 1800 | N11: 2400 | O11: 9600 | P11: 7200 | Q11: 2400 | R11: 0.25 | S11: Ibadan Depot | T11: BANK TRANSFER
A12: TXN-10011 | B12: 29-Mar-2026 | C12: March | D12: CUST2006 | E12: Tunde Bakare | F12: Male | G12: Wholesale | H12: Oyo | I12: PRD108 | J12: =VLOOKUP(I12,Product_Catalog!$A$1:$E$11,2,FALSE) -> Tomato Paste 400g | K12: Cooking Ingredients | L12: 22 | M12: 600 | N12: 850 | O12: 18700 | P12: 13200 | Q12: 5500 | R12: 0.29411765 | S12: Lagos Main | T12: CASH
A13: TXN-10012 | B13: 27-Apr-2026 | C13: April | D13: CUST2001 | E13: Amina Bello | F13: Female | G13: Retail | H13: Lagos | I13: PRD103 | J13: =VLOOKUP(I13,Product_Catalog!$A$1:$E$11,2,FALSE) -> Whole Milk Powder 400g | K13: Dairy | L13: 24 | M13: 1800 | N13: 2400 | O13: 57600 | P13: 43200 | Q13: 14400 | R13: 0.25 | S13: Abuja Central | T13: USSD
A14: TXN-10013 | B14: 10-Apr-2026 | C14: April | D14: CUST2005 | E14: Zainab Ibrahim | F14: Female | G14: Retail | H14: Lagos | I14: PRD103 | J14: =VLOOKUP(I14,Product_Catalog!$A$1:$E$11,2,FALSE) -> Whole Milk Powder 400g | K14: Dairy | L14: 18 | M14: 1800 | N14: 2400 | O14: 43200 | P14: 32400 | Q14: 10800 | R14: 0.25 | S14: Port Harcourt Hub | T14: POS
A15: TXN-10014 | B15: 14-Apr-2026 | C15: April | D15: CUST2001 | E15: Amina Bello | F15: Female | G15: Retail | H15: Lagos | I15: PRD103 | J15: =VLOOKUP(I15,Product_Catalog!$A$1:$E$11,2,FALSE) -> Whole Milk Powder 400g | K15: Dairy | L15: 3 | M15: 1800 | N15: 2400 | O15: 7200 | P15: 5400 | Q15: 1800 | R15: 0.25 | S15: Kano Retail | T15: BANK TRANSFER
A16: TXN-10015 | B16: 01-Jun-2026 | C16: June | D16: CUST2010 | E16: Blessing John | F16: Female | G16: Retail | H16: Abuja | I16: PRD105 | J16: =VLOOKUP(I16,Product_Catalog!$A$1:$E$11,2,FALSE) -> Vegetable Oil 1L | K16: Cooking Ingredients | L16: 19 | M16: 2200 | N16: 2900 | O16: 55100 | P16: 41800 | Q16: 13300 | R16: 0.24137931 | S16: Ibadan Depot | T16: CASH
A17: TXN-10016 | B17: 11-May-2026 | C17: May | D17: CUST2015 | E17: Hadiza Usman | F17: Female | G17: Wholesale | H17: Kaduna | I17: PRD107 | J17: =VLOOKUP(I17,Product_Catalog!$A$1:$E$11,2,FALSE) -> Basmati Rice 5kg | K17: Grains | L17: 14 | M17: 6500 | N17: 8500 | O17: 119000 | P17: 91000 | Q17: 28000 | R17: 0.23529412 | S17: Lagos Main | T17: USSD
A18: TXN-10017 | B18: 30-May-2026 | C18: May | D18: CUST2011 | E18: Kelechi Amadi | F18: Male | G18: Wholesale | H18: Enugu | I18: PRD107 | J18: =VLOOKUP(I18,Product_Catalog!$A$1:$E$11,2,FALSE) -> Basmati Rice 5kg | K18: Grains | L18: 2 | M18: 6500 | N18: 8500 | O18: 17000 | P18: 13000 | Q18: 4000 | R18: 0.23529412 | S18: Abuja Central | T18: POS
A19: TXN-10018 | B19: 22-Feb-2026 | C19: February | D19: CUST2015 | E19: Hadiza Usman | F19: Female | G19: Wholesale | H19: Kaduna | I19: PRD109 | J19: =VLOOKUP(I19,Product_Catalog!$A$1:$E$11,2,FALSE) -> Fruit Juice 1L | K19: Beverages | L19: 1 | M19: 750 | N19: 1100 | O19: 1100 | P19: 750 | Q19: 350 | R19: 0.31818182 | S19: Port Harcourt Hub | T19: BANK TRANSFER
A20: TXN-10019 | B20: 02-Jan-2026 | C20: January | D20: CUST2010 | E20: Blessing John | F20: Female | G20: Retail | H20: Abuja | I20: PRD110 | J20: =VLOOKUP(I20,Product_Catalog!$A$1:$E$11,2,FALSE) -> Toothpaste 140g | K20: Personal Care | L20: 3 | M20: 450 | N20: 650 | O20: 1950 | P20: 1350 | Q20: 600 | R20: 0.30769231 | S20: Kano Retail | T20: CASH
A21: TXN-10020 | B21: 29-Mar-2026 | C21: March | D21: CUST2015 | E21: Hadiza Usman | F21: Female | G21: Wholesale | H21: Kaduna | I21: PRD103 | J21: =VLOOKUP(I21,Product_Catalog!$A$1:$E$11,2,FALSE) -> Whole Milk Powder 400g | K21: Dairy | L21: 7 | M21: 1800 | N21: 2400 | O21: 16800 | P21: 12600 | Q21: 4200 | R21: 0.25 | S21: Ibadan Depot | T21: USSD
... A101: TXN-10100 | B101: 12-Jun-2026 | C101: June | D101: CUST2003 | E101: Funke Adebayo | F101: Female | G101: Retail | H101: Rivers | I101: PRD109 | J101: =VLOOKUP(I101,Product_Catalog!$A$1:$E$11,2,FALSE) -> Fruit Juice 1L | K101: Beverages | L101: 6 | M101: 750 | N101: 1100 | O101: 6600 | P101: 4500 | Q101: 2100 | R101: 0.31818182 | S101: Ibadan Depot | T101: USSD

Sheet Product_Catalog
A1: Product_ID | B1: Product_Name | C1: Category | D1: Unit_Cost_NGN | E1: Unit_Price_NGN
A2: PRD101 | B2: Malt Beverage 33cl | C2: Beverages | D2: 250 | E2: 350
A3: PRD102 | B3: Instant Noodles 70g | C3: Packaged Food | D3: 120 | E3: 180
A4: PRD103 | B4: Whole Milk Powder 400g | C4: Dairy | D4: 1800 | E4: 2400
A5: PRD104 | B5: Laundry Detergent 1kg | C5: Household | D5: 850 | E5: 1200
A6: PRD105 | B6: Vegetable Oil 1L | C6: Cooking Ingredients | D6: 2200 | E6: 2900
A7: PRD106 | B7: Toilet Soap 120g | C7: Personal Care | D7: 300 | E7: 450
A8: PRD107 | B8: Basmati Rice 5kg | C8: Grains | D8: 6500 | E8: 8500
A9: PRD108 | B9: Tomato Paste 400g | C9: Cooking Ingredients | D9: 600 | E9: 850
A10: PRD109 | B10: Fruit Juice 1L | C10: Beverages | D10: 750 | E10: 1100
A11: PRD110 | B11: Toothpaste 140g | C11: Personal Care | D11: 450 | E11: 650

Sheet Customer_Profiles
A1: Customer_ID | B1: Customer_Name | C1: Gender | D1: Customer_Segment | E1: Location_State
A2: CUST2001 | B2: Amina Bello | C2: Female | D2: Retail | E2: Lagos
A3: CUST2002 | B3: Chidi Okeke | C3: Male | D3: Wholesale | E3: Abuja
A4: CUST2003 | B4: Funke Adebayo | C4: Female | D4: Retail | E4: Rivers
A5: CUST2004 | B5: Emeka Nwosu | C5: Male | D5: Corporate | E5: Kano
A6: CUST2005 | B6: Zainab Ibrahim | C6: Female | D6: Retail | E6: Lagos
A7: CUST2006 | B7: Tunde Bakare | C7: Male | D7: Wholesale | E7: Oyo
A8: CUST2007 | B8: Ngozi Eze | C8: Female | D8: Retail | E8: Rivers
A9: CUST2008 | B9: Ibrahim Musa | C9: Male | D9: Retail | E9: Kaduna
A10: CUST2009 | B10: Yinka Ogundipe | C10: Male | D10: Corporate | E10: Lagos
A11: CUST2010 | B11: Blessing John | C11: Female | D11: Retail | E11: Abuja
A12: CUST2011 | B12: Kelechi Amadi | C12: Male | D12: Wholesale | E12: Enugu
... A16: CUST2015 | B16: Hadiza Usman | C16: Female | D16: Wholesale | E16: Kaduna
